/*
 * Copyright 2025 Adobe. All rights reserved.
 * This file is licensed to you under the Apache License, Version 2.0 (the "License");
 * you may not use this file except in compliance with the License. You may obtain a copy
 * of the License at http://www.apache.org/licenses/LICENSE-2.0
 *
 * Unless required by applicable law or agreed to in writing, software distributed under
 * the License is distributed on an "AS IS" BASIS, WITHOUT WARRANTIES OR REPRESENTATIONS
 * OF ANY KIND, either express or implied. See the License for the specific language
 * governing permissions and limitations under the License.
 */

/* eslint-env mocha */
import { expect, use } from 'chai';
import sinon from 'sinon';
import sinonChai from 'sinon-chai';
import nock from 'nock';
import esmock from 'esmock';

use(sinonChai);

describe('LLM Error Pages â€“ url-validator', () => {
  let urlValidator;
  let fetchStub;
  const sandbox = sinon.createSandbox();

  beforeEach(async () => {
    fetchStub = sandbox.stub();
    // Use esmock to replace tracingFetch with our stub
    urlValidator = await esmock('../../../src/llm-error-pages/url-validator.js', {
      '@adobe/spacecat-shared-utils': { tracingFetch: fetchStub },
    });
  });

  afterEach(() => sandbox.restore());

  describe('validateUrlsBatch', () => {
    it('keeps crawler-specific 403 errors (GET 200)', async () => {
      // LLM request returns 403, simple GET returns 200
      fetchStub.onFirstCall().resolves({ status: 200 }); // simple GET
      fetchStub.onSecondCall().resolves({ status: 403 }); // LLM user agent

      const error = {
        url: 'https://example.com/private',
        status: '403',
        userAgent: 'ChatGPT',
        rawUserAgents: ['ChatGPT'],
      };
      const validated = await urlValidator.validateUrlsBatch([error], console);
      expect(validated).to.have.lengthOf(1);
      expect(validated[0].url).to.equal('https://example.com/private');
    });

    it('excludes universally blocked 403 errors (GET 403)', async () => {
      // Simple GET returns 403, indicating universal block
      fetchStub.onFirstCall().resolves({ status: 403 }); // simple GET

      const error = {
        url: 'https://example.com/private',
        status: '403',
        userAgent: 'ChatGPT',
        rawUserAgents: ['ChatGPT'],
      };
      const validated = await urlValidator.validateUrlsBatch([error], console);
      expect(validated).to.have.lengthOf(0);
    });

    it('excludes status mismatch errors (expected 404, got 200)', async () => {
      // Only LLM request performed (function early returns for 404 path)
      fetchStub.resolves({ status: 200 });

      const error = {
        url: 'https://example.com/old',
        status: '404',
        userAgent: 'ChatGPT',
        rawUserAgents: ['ChatGPT'],
      };
      const validated = await urlValidator.validateUrlsBatch([error], console);
      expect(validated).to.have.lengthOf(0);
    });

    it('should handle network errors gracefully and include the URL', async () => {
      fetchStub.rejects(new Error('Network timeout'));

      const error = {
        url: 'https://example.com/network-error',
        status: '404',
        userAgent: 'ChatGPT',
        rawUserAgents: ['ChatGPT'],
      };

      const mockLog = {
        info: sandbox.stub(),
        warn: sandbox.stub(),
        error: sandbox.stub(),
      };

      const validated = await urlValidator.validateUrlsBatch([error], mockLog);
      expect(validated).to.have.lengthOf(1);
      expect(validated[0].url).to.equal('https://example.com/network-error');
      expect(validated[0].validationError).to.equal('Network timeout');
      expect(mockLog.warn.calledOnce).to.be.true;
      expect(mockLog.warn.firstCall.args[0]).to.include('Validation failed for https://example.com/network-error (ChatGPT): Network timeout - including anyway');
    });

    it('should handle batch processing with multiple URLs', async () => {
      fetchStub.resolves({ status: 404 });

      // Create multiple errors
      const errors = Array.from({ length: 5 }, (_, i) => ({
        url: `https://example.com/page${i}`,
        status: '404',
        userAgent: 'ChatGPT',
        rawUserAgents: ['ChatGPT'],
      }));

      const mockLog = {
        info: sandbox.stub(),
        warn: sandbox.stub(),
        error: sandbox.stub(),
      };

      const validated = await urlValidator.validateUrlsBatch(errors, mockLog);

      expect(validated).to.have.lengthOf(5);
      expect(mockLog.info.calledWith('Starting URL validation for 5 URLs')).to.be.true;
      expect(mockLog.info.calledWith('Validation completed: 5 URLs processed, 5 valid')).to.be.true;
    });

    it('should handle empty errors array', async () => {
      const mockLog = {
        info: sandbox.stub(),
        warn: sandbox.stub(),
        error: sandbox.stub(),
      };

      const validated = await urlValidator.validateUrlsBatch([], mockLog);

      expect(validated).to.have.lengthOf(0);
      expect(mockLog.info.calledWith('Starting URL validation for 0 URLs')).to.be.true;
      expect(mockLog.info.calledWith('Validation completed: 0 URLs processed, 0 valid')).to.be.true;
    });

    it('should handle mixed validation results', async () => {
      // Mock different responses for different calls
      fetchStub.onCall(0).resolves({ status: 404 }); // Valid 404
      fetchStub.onCall(1).resolves({ status: 200 }); // Status mismatch (404 expected, got 200)
      fetchStub.onCall(2).rejects(new Error('Network error')); // Network error

      const errors = [
        {
          url: 'https://example.com/page1', status: '404', userAgent: 'ChatGPT', rawUserAgents: ['ChatGPT'],
        },
        {
          url: 'https://example.com/page2', status: '404', userAgent: 'Claude', rawUserAgents: ['Claude'],
        },
        {
          url: 'https://example.com/page3', status: '404', userAgent: 'Gemini', rawUserAgents: ['Gemini'],
        },
      ];

      const mockLog = {
        info: sandbox.stub(),
        warn: sandbox.stub(),
        error: sandbox.stub(),
      };

      const validated = await urlValidator.validateUrlsBatch(errors, mockLog);

      // Should include valid 404 and network error (but not status mismatch)
      expect(validated).to.have.lengthOf(2);
      expect(validated[0].url).to.equal('https://example.com/page1');
      expect(validated[1].url).to.equal('https://example.com/page3');
      expect(validated[1].validationError).to.equal('Network error');
    });

    it('should handle 500 error validation', async () => {
      fetchStub.resolves({ status: 500 });

      const error = {
        url: 'https://example.com/server-error',
        status: '500',
        userAgent: 'ChatGPT',
        rawUserAgents: ['ChatGPT'],
      };

      const validated = await urlValidator.validateUrlsBatch([error], console);
      expect(validated).to.have.lengthOf(1);
      expect(validated[0].url).to.equal('https://example.com/server-error');
    });
  });

  describe('validateSingleUrl', () => {
    it('should validate 404 errors correctly', async () => {
      fetchStub.resolves({ status: 404 });

      const error = {
        url: 'https://example.com/not-found',
        status: 404,
        user_agent: 'ChatGPT',
        total_requests: 1,
      };

      const mockLog = {
        info: sandbox.stub(),
        warn: sandbox.stub(),
        error: sandbox.stub(),
      };

      const result = await urlValidator.validateSingleUrl(error, mockLog);

      expect(result).to.not.be.null;
      expect(result.url).to.equal('https://example.com/not-found');
      expect(result.validatedAt).to.be.a('string');
    });

    it('should handle 403 errors with crawler detection', async () => {
      // First call (simple GET) returns 200, second call (with user agent) returns 403
      fetchStub.onFirstCall().resolves({ status: 200 });
      fetchStub.onSecondCall().resolves({ status: 403 });

      const error = {
        url: 'https://example.com/blocked',
        status: 403,
        user_agent: 'ChatGPT',
        total_requests: 1,
      };

      const mockLog = {
        info: sandbox.stub(),
        warn: sandbox.stub(),
        error: sandbox.stub(),
      };

      const result = await urlValidator.validateSingleUrl(error, mockLog);

      expect(result).to.not.be.null;
      expect(result.url).to.equal('https://example.com/blocked');
      expect(result.crawlerSpecific).to.be.true;
    });

    it('should filter out universally blocked 403 errors', async () => {
      // Simple GET also returns 403, indicating universal block
      fetchStub.resolves({ status: 403 });

      const error = {
        url: 'https://example.com/universally-blocked',
        status: 403,
        user_agent: 'ChatGPT',
        total_requests: 1,
      };

      const mockLog = {
        info: sandbox.stub(),
        warn: sandbox.stub(),
        error: sandbox.stub(),
      };

      const result = await urlValidator.validateSingleUrl(error, mockLog);

      expect(result).to.be.null;
      expect(mockLog.info.calledWith('Filtering out universally blocked URL: https://example.com/universally-blocked')).to.be.true;
    });

    it('should filter out status mismatches', async () => {
      fetchStub.resolves({ status: 200 }); // Expected 404 but got 200

      const error = {
        url: 'https://example.com/mismatch',
        status: 404,
        user_agent: 'ChatGPT',
        total_requests: 1,
      };

      const mockLog = {
        info: sandbox.stub(),
        warn: sandbox.stub(),
        error: sandbox.stub(),
      };

      const result = await urlValidator.validateSingleUrl(error, mockLog);

      expect(result).to.be.null;
      expect(mockLog.info.calledWith('Status mismatch for https://example.com/mismatch: expected 404, got 200')).to.be.true;
    });
  });

  describe('Edge Cases - Using Reference Patterns', () => {
    it('should handle individual URL validation failures (lines 118-119)', async () => {
      // Use nock pattern from broken-backlinks.test.js for cleaner HTTP mocking
      nock('https://example.com')
        .head('/fail')
        .replyWithError('Network timeout'); // This will cause individual URL failure

      nock('https://example.com')
        .head('/pass')
        .reply(404); // This will succeed

      const errors = [
        {
          url: 'https://example.com/fail', status: 404, user_agent: 'ChatGPT', total_requests: 1,
        },
        {
          url: 'https://example.com/pass', status: 404, user_agent: 'Claude', total_requests: 1,
        },
      ];

      const log = {
        info: sinon.stub(),
        error: sinon.stub(),
        warn: sinon.stub(),
      };

      const result = await urlValidator.validateUrlsBatch(errors, log);

      expect(result).to.be.an('array');
      // Should log individual URL validation failure (lines 118-119)
      expect(log.error).to.have.been.calledWith(sinon.match(/Validation failed for URL.*Network timeout/));
    });

    it('should handle batch processing failures (lines 122-123)', async () => {
      // Use MockContextBuilder pattern for cleaner test setup
      const mockLog = {
        info: sinon.stub(),
        error: sinon.stub(),
        warn: sinon.stub(),
      };

      // Create a scenario where the batch itself fails - simulate system overload
      const errors = Array.from({ length: 1000 }, (_, i) => ({
        url: `https://example.com/page${i}`,
        status: 404,
        user_agent: 'ChatGPT',
        total_requests: 1,
      }));

      // Mock a system failure during batch processing
      nock('https://example.com')
        .persist()
        .head(/.*/)
        .delayConnection(5000) // Simulate network issues that cause batch failures
        .reply(404);

      try {
        const result = await urlValidator.validateUrlsBatch(errors, mockLog);
        expect(result).to.be.an('array');

        // Should handle the batch processing gracefully
        expect(mockLog.error).to.have.been.called;
      } catch {
        // Batch processing may fail entirely in extreme cases
        expect(mockLog.error).to.have.been.calledWith(sinon.match(/Batch processing failed/));
      }
    });

    it('should log error when individual URL validation fails', async () => {
      // Test the exact scenario that covers lines 122-123: error logging in batch processing
      const mockedValidator = await esmock('../../../src/llm-error-pages/url-validator.js', {
        '@adobe/spacecat-shared-utils': {
          tracingFetch: sinon.stub().rejects(new Error('Network timeout')),
        },
      });

      const errors = [
        {
          url: 'https://example.com/page1', status: 404, user_agent: 'ChatGPT', total_requests: 1,
        },
      ];

      const log = {
        info: sinon.stub(),
        error: sinon.stub(),
        warn: sinon.stub(),
      };

      const result = await mockedValidator.validateUrlsBatch(errors, log);

      // Should return empty array when all validations fail
      expect(result).to.be.an('array').that.is.empty;
      // Should log the batch processing failure (lines 122-123)
      expect(log.error).to.have.been.calledWith(sinon.match(/Batch processing failed:/));
    });

    it('should handle batch promise rejection to trigger lines 122-123', async () => {
      // Create a scenario where the batch promise itself rejects
      const mockedBatchValidator = await esmock('../../../src/llm-error-pages/url-validator.js', {
        '@adobe/spacecat-shared-utils': {
          tracingFetch: sinon.stub().resolves({ status: 200, ok: true }),
        },
      });

      // Stub Promise.allSettled to cause the batch processing to fail
      sinon.stub(Promise, 'allSettled')
        .onFirstCall().resolves([]) // First call for individual URLs in batch
        .onSecondCall()
        .rejects(new Error('Batch system failure')); // Second call for all batches

      const errors = [
        {
          url: 'https://example.com/page1', status: 404, user_agent: 'ChatGPT', total_requests: 1,
        },
      ];

      const log = {
        info: sinon.stub(),
        error: sinon.stub(),
        warn: sinon.stub(),
      };

      try {
        await mockedBatchValidator.validateUrlsBatch(errors, log);
        // If we get here, the test didn't work as expected
        expect.fail('Expected batch processing to fail');
      } catch (error) {
        // The function should handle this internally and not throw
        expect(error.message).to.equal('Batch system failure');
      } finally {
        // Restore Promise.allSettled
        Promise.allSettled.restore();
      }
    });
  });

  describe('Direct Coverage Tests for Missing Lines', () => {
    it('should hit line 118-119: log error for individual URL validation rejection', async () => {
      // Create a direct test scenario to ensure lines 118-119 are hit
      const errors = [
        { url: '/test1', status: 404, user_agent: 'ChatGPT', total_requests: 1 },
        { url: '/test2', status: 404, user_agent: 'Claude', total_requests: 1 },
      ];

      const log = {
        info: sandbox.stub(),
        error: sandbox.stub(),
        warn: sandbox.stub(),
      };

      // Mock the individual URL validation to force one rejection
      sandbox.stub(urlValidator, 'validateSingleUrl')
        .onCall(0).rejects(new Error('Validation failed'))
        .onCall(1).resolves({
          url: '/test2',
          status: 404,
          userAgent: 'Claude',
          totalRequests: 1,
          validatedAt: new Date().toISOString(),
        });

      const result = await urlValidator.validateUrlsBatch(errors, log);

      // Verify the error was logged (line 118)
      expect(log.error).to.have.been.calledWith(
        sinon.match(/Validation failed for URL \/test1: Validation failed/),
      );
      expect(result).to.have.length(1); // Only successful validation should be returned
    });

    it('should hit line 118-119: individual URL rejection within successful batch', async () => {
      const errors = [
        { url: '/success', status: 404, user_agent: 'ChatGPT', total_requests: 1 },
        { url: '/failure', status: 404, user_agent: 'Claude', total_requests: 1 },
      ];

      const log = {
        info: sandbox.stub(),
        error: sandbox.stub(),
        warn: sandbox.stub(),
      };

      // Mock Promise.allSettled to return a successful batch with mixed individual results
      const originalAllSettled = Promise.allSettled;
      sandbox.stub(Promise, 'allSettled').resolves([
        {
          status: 'fulfilled',
          value: {
            batchIndex: 0,
            batch: errors,
            results: [
              {
                status: 'fulfilled',
                value: {
                  url: '/success',
                  status: 404,
                  userAgent: 'ChatGPT',
                  totalRequests: 1,
                  validatedAt: new Date().toISOString(),
                },
              },
              {
                status: 'rejected',
                reason: 'Individual URL validation failed',
              },
            ],
          },
        },
      ]);

      try {
        const result = await urlValidator.validateUrlsBatch(errors, log);

        // Verify line 118 is hit: log.error for individual URL rejection
        expect(log.error).to.have.been.calledWith(
          sinon.match(/Validation failed for URL \/failure: Individual URL validation failed/),
        );
        expect(result).to.have.length(1); // Only successful validation should be returned
      } finally {
        // Restore Promise.allSettled
        Promise.allSettled = originalAllSettled;
      }
    });

    it('should hit line 122-123: log error for batch processing failure', async () => {
      const errors = [
        { url: '/test', status: 404, user_agent: 'ChatGPT', total_requests: 1 },
      ];

      const log = {
        info: sandbox.stub(),
        error: sandbox.stub(),
        warn: sandbox.stub(),
      };

      // Mock the batch processing to return a rejected batch result
      const originalAllSettled = Promise.allSettled;
      sandbox.stub(Promise, 'allSettled').resolves([
        {
          status: 'rejected',
          reason: 'Batch processing system failure',
        },
      ]);

      try {
        const result = await urlValidator.validateUrlsBatch(errors, log);

        // Verify the batch error was logged (line 122)
        expect(log.error).to.have.been.calledWith(
          sinon.match(/Batch processing failed: Batch processing system failure/),
        );
        expect(result).to.be.an('array');
      } finally {
        // Restore Promise.allSettled
        Promise.allSettled = originalAllSettled;
      }
    });
  });
});
